INFO 2024-07-04 10:57:30,687 [torch.distributed.nn.jit.instantiator:instantiator.py:<module>:21]
Created a temporary directory at /var/folders/94/p22yrw514tv4kplhpq9hmknr0000gn/T/tmppb3hl7fh

INFO 2024-07-04 10:57:30,689 [torch.distributed.nn.jit.instantiator:instantiator.py:_write:76]
Writing /var/folders/94/p22yrw514tv4kplhpq9hmknr0000gn/T/tmppb3hl7fh/_remote_module_non_scriptable.py

INFO 2024-07-04 12:21:04,019 [root:accelerator.py:_autodetect_tpu_version:216]
Unable to poll TPU GCE metadata: HTTPConnectionPool(host='metadata.google.internal', port=80): Max retries exceeded with url: /computeMetadata/v1/instance/attributes/accelerator-type (Caused by NewConnectionError('<urllib3.connection.HTTPConnection object at 0x332c44100>: Failed to establish a new connection: [Errno 8] nodename nor servname provided, or not known'))

INFO 2024-07-04 12:21:04,027 [root:accelerator.py:_autodetect_num_tpus:171]
Failed to detect number of TPUs: [Errno 2] No such file or directory: '/dev/vfio'

